Workbook

Sheet Hướng dẫn
B1: Checklist nghiệm thu demo — DAFC
B2: Bản phát hành 04/09/2026 · demo e-commerce (mobile + desktop + trang chủ)
B4: File này dùng để làm gì
B5: Đối chiếu từng trang / thành phần của bản demo, đánh dấu cái nào đã đạt, cái nào cần chỉnh, và đếm số lần chỉnh sửa của từng hạng mục.
B7: Ô nào anh/chị điền
B8: Chỉ 3 cột cuối của mỗi bảng, đã tô NỀN VÀNG NHẠT:
B9: • Khách duyệt — bấm vào ô sẽ hiện danh sách chọn (☐ Chưa duyệt · ☑ Đạt · ✎ Cần chỉnh sửa · — Không áp dụng).
B10: • Số lần chỉnh sửa — tất cả đang là 0; mỗi lần yêu cầu chỉnh được xử lý xong thì cộng thêm 1.
B11: • Ghi chú / yêu cầu chỉnh sửa — mô tả cụ thể chỗ cần sửa.
B12: Các cột còn lại là hiện trạng bản dựng, để nguyên giúp bên thiết kế đối chiếu.
B14: Ví dụ một dòng đã điền
B16: Trang / màn hình | C16: Khách duyệt | D16: Số lần chỉnh sửa | E16: Ghi chú / yêu cầu chỉnh sửa
B17: Giỏ hàng | C17: ✎ Cần chỉnh sửa | D17: 1 | E17: Đổi nhãn nút thanh toán thành “Đặt hàng”
B19: Chú giải các ký hiệu trong bảng
B20: ✓ Có | C20: hạng mục đã dựng trong bản đó
B21: ✗ Chưa có | C21: chưa dựng trong bản đó
B22: — Không áp dụng | C22: bản đó không có hạng mục này theo thiết kế, không phải thiếu sót
B24: Cách đếm số lần chỉnh sửa
B25: Bộ đếm bắt đầu lại từ 0 kể từ đợt nghiệm thu này (04/09/2026) — các vòng chỉnh trong giai đoạn dựng demo trước đó không tính vào đây.
B26: Quy ước: một lần chỉnh = một yêu cầu của khách đã được xử lý xong và gửi lại bản cập nhật.
B28: Các bảng trong file
B29: Trang & màn hình | C29: 26 trang/màn của bản mobile, desktop và trang chủ
B30: Thành phần UI | C30: 61 thành phần dùng lại nhiều nơi (header, thẻ sản phẩm, bộ lọc…)
B31: Phiên bản | C31: 6 file bàn giao và trạng thái từng file
B32: Tổng hợp | C32: đếm tự động theo trạng thái anh/chị chọn — không cần điền
B34: Về trang sản phẩm (PDP)
B35: Trong quá trình dựng demo có 6 biến thể PDP để so sánh bố cục. Nay chốt lấy BẢN 1 làm chuẩn, nên checklist chỉ có một dòng “Trang sản phẩm (PDP)”; 5 biến thể còn lại không đưa vào nghiệm thu.
B37: Lưu ý về 3 bản thử skin
B38: desktop-neutral · desktop-editorial · desktop-atelier là 3 phương án THỬ giao diện, dừng cập nhật từ 21/08/2026. Chúng thiếu 12 hạng mục so với bản chính và không mang bộ font Libre Bodoni + Inter đã chốt ngày 03/09.
B39: Nếu anh/chị chỉ nghiệm thu bản chính, đánh dấu 3 bản này là “— Không áp dụng” ở bảng Phiên bản.

Sheet Trang & màn hình
A1: Bảng 1 — Trang & màn hình
A2: Cột tô vàng là phần anh/chị điền; bộ đếm chỉnh sửa bắt đầu từ 0. Trang chủ nằm ở file riêng home.html (một file chạy cả hai khổ màn hình); các trang còn lại ở index.html và desktop.html.
A3: STT | B3: Trang / màn hình | C3: Mã kỹ thuật | D3: Bản mobile (dưới 768px) | E3: Bản desktop (từ 768px) | F3: Tình trạng dựng | G3: Cập nhật gần nhất | H3: Khách duyệt | I3: Số lần chỉnh sửa | J3: Ghi chú / yêu cầu chỉnh sửa
A4: TRANG CHỦ · home.html
A5: 1 | B5: Trang chủ — ngành Nam | C5: home.html · nam | D5: ✓ Có | E5: ✓ Có | F5: Hoàn tất — file riêng home.html | G5: 46268 | H5: ☐ Chưa duyệt | I5: 0
A6: 2 | B6: Trang chủ — ngành Nữ | C6: home.html · nu | D6: ✓ Có | E6: ✓ Có | F6: Hoàn tất — file riêng home.html | G6: 46268 | H6: ☐ Chưa duyệt | I6: 0
A7: 3 | B7: Trang chủ — ngành Làm đẹp | C7: home.html · beauty | D7: ✓ Có | E7: ✓ Có | F7: Hoàn tất — file riêng home.html | G7: 46268 | H7: ☐ Chưa duyệt | I7: 0
A8: DANH MỤC & TÌM KIẾM
A9: 4 | B9: Danh sách sản phẩm (PLP) | C9: plp | D9: ✓ Có | E9: ✓ Có | F9: Hoàn tất | G9: 46268 | H9: ☐ Chưa duyệt | I9: 0
A10: 5 | B10: Trang thương hiệu (5 hãng) | C10: BRAND_PAGES | D10: ✓ Có | E10: ✓ Có | F10: Hoàn tất — 3 bản thử chưa áp | G10: 46267 | H10: ☐ Chưa duyệt | I10: 0
A11: 6 | B11: Tìm kiếm | C11: search | D11: ✓ Có | E11: ✓ Có | F11: Hoàn tất | G11: 46253 | H11: ☐ Chưa duyệt | I11: 0
A12: 7 | B12: Bộ lọc (panel đầy đủ) | C12: filter panel | D12: ✓ Có | E12: ✓ Có | F12: Hoàn tất — chờ chốt mức giá | G12: 46268 | H12: ☐ Chưa duyệt | I12: 0
A13: TRANG SẢN PHẨM
A14: 8 | B14: Trang sản phẩm (PDP) | C14: pdp | D14: ✓ Có | E14: ✓ Có | F14: Hoàn tất — bản 1 là bản chuẩn | G14: 46269 | H14: ☐ Chưa duyệt | I14: 0
A15: GIỎ HÀNG & THANH TOÁN
A16: 9 | B16: Giỏ hàng | C16: cart | D16: ✓ Có | E16: ✓ Có | F16: Hoàn tất | G16: 46268 | H16: ☐ Chưa duyệt | I16: 0
A17: 10 | B17: Thanh toán | C17: checkout | D17: ✓ Có | E17: ✓ Có | F17: Hoàn tất — chờ chốt cọc đặt trước | G17: 46255 | H17: ☐ Chưa duyệt | I17: 0
A18: 11 | B18: Hoàn tất đơn hàng | C18: done | D18: ✓ Có | E18: ✓ Có | F18: Hoàn tất | G18: 46245 | H18: ☐ Chưa duyệt | I18: 0
A19: 12 | B19: Chi tiết đơn hàng | C19: order | D19: ✓ Có | E19: ✓ Có | F19: Hoàn tất | G19: 46254 | H19: ☐ Chưa duyệt | I19: 0
A20: ĐĂNG NHẬP & TÀI KHOẢN
A21: 13 | B21: Đăng nhập | C21: login | D21: ✓ Có | E21: ✓ Có | F21: Hoàn tất | G21: 46255 | H21: ☐ Chưa duyệt | I21: 0
A22: 14 | B22: Đăng ký (nhập số điện thoại) | C22: register | D22: ✓ Có | E22: ✓ Có | F22: Hoàn tất | G22: 46255 | H22: ☐ Chưa duyệt | I22: 0
A23: 15 | B23: Xác thực OTP 6 ô | C23: otp | D23: ✓ Có | E23: ✓ Có | F23: Hoàn tất | G23: 46255 | H23: ☐ Chưa duyệt | I23: 0
A24: 16 | B24: Hoàn tất đăng ký (họ tên · email · mật khẩu) | C24: reginfo | D24: ✓ Có | E24: ✓ Có | F24: Hoàn tất — chưa có bản vẽ Figma riêng | G24: 46255 | H24: ☐ Chưa duyệt | I24: 0
A25: 17 | B25: Quên mật khẩu | C25: forgot | D25: ✓ Có | E25: ✓ Có | F25: Hoàn tất | G25: 46255 | H25: ☐ Chưa duyệt | I25: 0
A26: 18 | B26: Đặt lại mật khẩu | C26: setpass | D26: ✓ Có | E26: ✓ Có | F26: Hoàn tất | G26: 46255 | H26: ☐ Chưa duyệt | I26: 0
A27: 19 | B27: Tài khoản — Thông tin | C27: account · info | D27: ✓ Có | E27: ✓ Có | F27: Hoàn tất — chưa có trạng thái lỗi/rỗng | G27: 46251 | H27: ☐ Chưa duyệt | I27: 0
A28: 20 | B28: Tài khoản — Đơn hàng | C28: account · orders | D28: ✓ Có | E28: ✓ Có | F28: Hoàn tất — chưa có trạng thái rỗng | G28: 46251 | H28: ☐ Chưa duyệt | I28: 0
A29: 21 | B29: Tài khoản — Địa chỉ | C29: account · address | D29: ✓ Có | E29: ✓ Có | F29: Hoàn tất — chưa có trạng thái rỗng | G29: 46251 | H29: ☐ Chưa duyệt | I29: 0
A30: 22 | B30: Tài khoản — Thành viên | C30: account · loyalty | D30: ✓ Có | E30: ✓ Có | F30: Hoàn tất | G30: 46251 | H30: ☐ Chưa duyệt | I30: 0
A31: 23 | B31: Tài khoản — Điểm thưởng | C31: account · points | D31: ✓ Có | E31: ✓ Có | F31: Hoàn tất — chưa có trạng thái rỗng | G31: 46251 | H31: ☐ Chưa duyệt | I31: 0
A32: TRANG TĨNH / CHÍNH SÁCH
A33: 24 | B33: Chính sách bảo mật | C33: privacy | D33: ✓ Có | E33: ✓ Có | F33: Hoàn tất | G33: 46246 | H33: ☐ Chưa duyệt | I33: 0
A34: 25 | B34: Điều khoản dịch vụ | C34: terms | D34: ✓ Có | E34: ✓ Có | F34: Hoàn tất | G34: 46246 | H34: ☐ Chưa duyệt | I34: 0
A35: 26 | B35: Chính sách đổi trả | C35: returns | D35: ✓ Có | E35: ✓ Có | F35: Hoàn tất | G35: 46246 | H35: ☐ Chưa duyệt | I35: 0

Sheet Thành phần UI
A1: Bảng 2 — Thành phần giao diện dùng lại
A2: Một thành phần xuất hiện ở nhiều trang; duyệt ở đây là duyệt cho mọi trang có dùng nó.
A3: STT | B3: Thành phần | C3: Tên kỹ thuật | D3: Bản mobile (index.html) | E3: Bản desktop (desktop.html) | F3: Cập nhật gần nhất | G3: Khách duyệt | H3: Số lần chỉnh sửa | I3: Ghi chú / yêu cầu chỉnh sửa
A4: KHUNG TRANG
A5: 1 | B5: Thanh khuyến mãi trên cùng | C5: promo bar | D5: ✓ Có | E5: ✓ Có | F5: 46258 | G5: ☐ Chưa duyệt | H5: 0
A6: 2 | B6: Header mobile | C6: page-header-mobile | D6: ✓ Có | E6: — Không áp dụng | F6: 46269 | G6: ☐ Chưa duyệt | H6: 0
A7: 3 | B7: Header desktop + thanh danh mục | C7: page-header-desktop | D7: — Không áp dụng | E7: ✓ Có | F7: 46269 | G7: ☐ Chưa duyệt | H7: 0
A8: 4 | B8: Menu mobile (3 ngành, submenu) | C8: MENU_DATA | D8: ✓ Có | E8: — Không áp dụng | F8: 46269 | G8: ☐ Chưa duyệt | H8: 0
A9: 5 | B9: Mega menu desktop 3 cột | C9: DK_NAV_CATS | D9: — Không áp dụng | E9: ✓ Có | F9: 46269 | G9: ☐ Chưa duyệt | H9: 0
A10: 6 | B10: Ô tìm kiếm trên header | C10: search box | D10: ✓ Có | E10: ✓ Có | F10: 46253 | G10: ☐ Chưa duyệt | H10: 0
A11: 7 | B11: Đường dẫn phân cấp (breadcrumb) | C11: breadcrumbs | D11: — Không áp dụng | E11: ✓ Có | F11: 46268 | G11: ☐ Chưa duyệt | H11: 0
A12: 8 | B12: Khối cam kết dịch vụ | C12: service-promises | D12: ✓ Có | E12: ✓ Có | F12: 46260 | G12: ☐ Chưa duyệt | H12: 0
A13: 9 | B13: Footer mobile | C13: page-footer-mobile | D13: ✓ Có | E13: — Không áp dụng | F13: 46260 | G13: ☐ Chưa duyệt | H13: 0
A14: 10 | B14: Footer desktop | C14: page-footer-desktop | D14: — Không áp dụng | E14: ✓ Có | F14: 46260 | G14: ☐ Chưa duyệt | H14: 0
A15: 11 | B15: Nút cài đặt (đổi ngôn ngữ · font · bộ da) | C15: settings FAB | D15: ✓ Có | E15: ✓ Có | F15: 46259 | G15: ☐ Chưa duyệt | H15: 0
A16: 12 | B16: Nút lên đầu trang | C16: #topFab | D16: ✓ Có | E16: ✓ Có | F16: 46267 | G16: ☐ Chưa duyệt | H16: 0
A17: THẺ SẢN PHẨM & DANH SÁCH
A18: 13 | B18: Thẻ sản phẩm — lưới | C18: product-item-info | D18: ✓ Có | E18: ✓ Có | F18: 46268 | G18: ☐ Chưa duyệt | H18: 0
A19: 14 | B19: Thẻ sản phẩm — dải trượt ngang | C19: product-item-info · rail | D19: ✓ Có | E19: ✓ Có | F19: 46268 | G19: ☐ Chưa duyệt | H19: 0
A20: 15 | B20: Nhãn trên ảnh (Best seller, quà tặng…) | C20: badge on-image | D20: ✓ Có | E20: ✓ Có | F20: 46253 | G20: ☐ Chưa duyệt | H20: 0
A21: 16 | B21: Nhãn “Đặt trước” đứng trước tên | C21: badge pre-order | D21: ✓ Có | E21: ✓ Có | F21: 46268 | G21: ☐ Chưa duyệt | H21: 0
A22: 17 | B22: Ô chọn màu ở thẻ sản phẩm | C22: swatch-option | D22: ✓ Có | E22: ✓ Có | F22: 46259 | G22: ☐ Chưa duyệt | H22: 0
A23: 18 | B23: Giá gốc / giá giảm / chip −% | C23: price-box | D23: ✓ Có | E23: ✓ Có | F23: 46268 | G23: ☐ Chưa duyệt | H23: 0
A24: 19 | B24: Thêm nhanh vào giỏ (nút trên thẻ) | C24: quick-add | D24: ✓ Có | E24: ✓ Có | F24: 46268 | G24: ☐ Chưa duyệt | H24: 0
A25: 20 | B25: Thanh công cụ PLP (sắp xếp · số SP) | C25: toolbar | D25: ✓ Có | E25: ✓ Có | F25: 46268 | G25: ☐ Chưa duyệt | H25: 0
A26: 21 | B26: Nút đổi mật độ lưới (1 / 2 cột) | C26: gridbtn | D26: ✓ Có | E26: ✓ Có | F26: 46268 | G26: ☐ Chưa duyệt | H26: 0
A27: 22 | B27: Chip bộ lọc đang chọn | C27: filter-chip | D27: ✓ Có | E27: ✓ Có | F27: 46262 | G27: ☐ Chưa duyệt | H27: 0
A28: 23 | B28: Nút “Xem thêm” + thanh tiến trình | C28: action more | D28: ✓ Có | E28: ✓ Có | F28: 46268 | G28: ☐ Chưa duyệt | H28: 0
A29: BỘ LỌC
A30: 24 | B30: Panel bộ lọc (khung chung) | C30: filter panel | D30: ✓ Có | E30: ✓ Có | F30: 46268 | G30: ☐ Chưa duyệt | H30: 0
A31: 25 | B31: Cây danh mục 3 tầng (8/57/172) | C31: FILTER_CATS | D31: ✓ Có | E31: ✓ Có | F31: 46261 | G31: ☐ Chưa duyệt | H31: 0
A32: 26 | B32: Lọc màu (15 màu) | C32: color | D32: ✓ Có | E32: ✓ Có | F32: 46260 | G32: ☐ Chưa duyệt | H32: 0
A33: 27 | B33: Lọc kích cỡ | C33: size | D33: ✓ Có | E33: ✓ Có | F33: 46260 | G33: ☐ Chưa duyệt | H33: 0
A34: 28 | B34: Lọc thương hiệu (24 hãng + ô tìm) | C34: brand | D34: ✓ Có | E34: ✓ Có | F34: 46261 | G34: ☐ Chưa duyệt | H34: 0
A35: 29 | B35: Lọc khoảng giá | C35: price | D35: ✓ Có | E35: ✓ Có | F35: 46260 | G35: ☐ Chưa duyệt | H35: 0
A36: 30 | B36: Lọc ưu đãi | C36: promo | D36: ✓ Có | E36: ✓ Có | F36: 46253 | G36: ☐ Chưa duyệt | H36: 0
A37: 31 | B37: Lọc độ cao giày | C37: heel | D37: ✓ Có | E37: ✓ Có | F37: 46260 | G37: ☐ Chưa duyệt | H37: 0
A38: TRANG SẢN PHẨM
A39: 32 | B39: Bộ ảnh sản phẩm + xem phóng to | C39: product-media | D39: ✓ Có | E39: ✓ Có | F39: 46262 | G39: ☐ Chưa duyệt | H39: 0
A40: 33 | B40: Chọn kích cỡ dạng chip | C40: swatch-option · size | D40: ✓ Có | E40: ✓ Có | F40: 46269 | G40: ☐ Chưa duyệt | H40: 0
...

Sheet Phiên bản
A1: Bảng 3 — Các phiên bản bàn giao
A2: 3 bản thử chỉ để so sánh hướng giao diện; nếu không nghiệm thu, chọn “— Không áp dụng”.
A3: STT | B3: Tên file | C3: Vai trò | D3: Phạm vi hiển thị | E3: Tình trạng | F3: Cập nhật gần nhất | G3: Khách duyệt | H3: Số lần chỉnh sửa | I3: Ghi chú / yêu cầu chỉnh sửa
A4: BẢN CHÍNH — dùng để nghiệm thu
A5: 1 | B5: index.html | C5: Bản mobile | D5: Dưới 768px, thiết kế theo khổ 360–412px | E5: Đang cập nhật | F5: 46269 | G5: ☐ Chưa duyệt | H5: 0
A6: 2 | B6: desktop.html | C6: Bản desktop | D6: Từ 768px trở lên, nội dung bó trong 1440px | E6: Đang cập nhật | F6: 46269 | G6: ☐ Chưa duyệt | H6: 0
A7: 3 | B7: home.html | C7: Trang chủ 3 ngành | D7: Một file gồm 3 màn: Nam · Nữ · Làm đẹp | E7: Đang cập nhật | F7: 46268 | G7: ☐ Chưa duyệt | H7: 0
A8: BẢN THỬ GIAO DIỆN — dừng cập nhật từ 21/08/2026
A9: 4 | B9: desktop-neutral.html | C9: Phương án màu greige ấm | D9: Thử bảng màu trung tính | E9: Đóng băng — thiếu 12 hạng mục so với bản chính | F9: 46255 | G9: ☐ Chưa duyệt | H9: 0
A10: 5 | B10: desktop-editorial.html | C10: Phương án bố cục editorial | D10: Thử nhịp trang theo hướng tạp chí | E10: Đóng băng — thiếu 12 hạng mục so với bản chính | F10: 46255 | G10: ☐ Chưa duyệt | H10: 0
A11: 6 | B11: desktop-atelier.html | C11: Phương án atelier | D11: Thử bộ da thứ ba | E11: Đóng băng — thiếu 12 hạng mục so với bản chính | F11: 46255 | G11: ☐ Chưa duyệt | H11: 0

Sheet Tổng hợp
B2: Tổng hợp tiến độ nghiệm thu
B3: Bảng này tự tính theo lựa chọn ở 3 bảng trước — anh/chị không cần điền gì.
B5: Bảng | C5: Tổng số dòng | D5: ☑ Đạt | E5: ✎ Cần chỉnh sửa | F5: ☐ Chưa duyệt | G5: — Không áp dụng | H5: Tỷ lệ đã duyệt | I5: Tổng số lần chỉnh sửa
B6: Trang & màn hình | C6: =COUNTA('Trang & màn hình'!$C$4:$C$35) | D6: =COUNTIF('Trang & màn hình'!$H$4:$H$35,"☑ Đạt") | E6: =COUNTIF('Trang & màn hình'!$H$4:$H$35,"✎ Cần chỉnh sửa") | F6: =COUNTIF('Trang & màn hình'!$H$4:$H$35,"☐ Chưa duyệt") | G6: =COUNTIF('Trang & màn hình'!$H$4:$H$35,"— Không áp dụng") | H6: =IFERROR(D6/(C6-G6),0) | I6: =SUM('Trang & màn hình'!$I$4:$I$35)
B7: Thành phần UI | C7: =COUNTA('Thành phần UI'!$C$4:$C$71) | D7: =COUNTIF('Thành phần UI'!$G$4:$G$71,"☑ Đạt") | E7: =COUNTIF('Thành phần UI'!$G$4:$G$71,"✎ Cần chỉnh sửa") | F7: =COUNTIF('Thành phần UI'!$G$4:$G$71,"☐ Chưa duyệt") | G7: =COUNTIF('Thành phần UI'!$G$4:$G$71,"— Không áp dụng") | H7: =IFERROR(D7/(C7-G7),0) | I7: =SUM('Thành phần UI'!$H$4:$H$71)
B8: Phiên bản | C8: =COUNTA('Phiên bản'!$C$4:$C$11) | D8: =COUNTIF('Phiên bản'!$G$4:$G$11,"☑ Đạt") | E8: =COUNTIF('Phiên bản'!$G$4:$G$11,"✎ Cần chỉnh sửa") | F8: =COUNTIF('Phiên bản'!$G$4:$G$11,"☐ Chưa duyệt") | G8: =COUNTIF('Phiên bản'!$G$4:$G$11,"— Không áp dụng") | H8: =IFERROR(D8/(C8-G8),0) | I8: =SUM('Phiên bản'!$H$4:$H$11)
B9: TỔNG | C9: =SUM(C6:C8) | D9: =SUM(D6:D8) | E9: =SUM(E6:E8) | F9: =SUM(F6:F8) | G9: =SUM(G6:G8) | H9: =IFERROR(D9/(C9-G9),0) | I9: =SUM(I6:I8)
B11: Cách đọc:
B12: • “Tỷ lệ đã duyệt” = số dòng ☑ Đạt chia cho tổng số dòng, đã trừ các dòng “— Không áp dụng”.
B13: • “Tổng số lần chỉnh sửa” cộng từ cột cùng tên ở 3 bảng; bộ đếm bắt đầu từ 0 kể từ 04/09/2026.
B14: • Khi chưa chọn trạng thái nào, tỷ lệ đã duyệt hiển thị 0% — chọn xong bảng tự cập nhật.
